Workbook

Sheet Cover
B1: NIKE, INC. (NKE) - VALUATION & INVESTMENT THESIS
B2: Model Date: January 17, 2026 | Analyst: Edney Naife
K3: PV of 3-Year Cash Flows | L3: =DCF!C25 -> 8594.0836
K4: PV of Terminal Value | L4: =DCF!E24 -> 63169.956
B6: RECOMMENDATION | C6: SELL | E6: Investment Thesis: Operational Recovery Priced to Perfection
E7: 1. The View: Nike is fundamentally sound but currently overvalued. Our DCF model yields an Intrinsic Value of $48.17, representing significant downside to the current trading price. The market appears to be pricing in a rapid "V-shaped" recovery that the financials do not yet support.
B8: Current Share Price: | C8: 64.38 | E8: 2. Key Assumptions:
B9: Target Price (Base Case): | C9: =DCF!C30 -> 48.165207 | E9: Margins: Modeled an aggressive recovery in EBIT margins from 7.5% (2026) to 13.0% (2028) as inventory issues clear. Even with this optimism, the valuation does not reach $64.
B10: Upside/ (Downside) | C10: =(C9/C8)-1 -> -0.25186072 | E10: Balance Sheet: Nike maintains a "Fortress Balance Sheet" with Net Debt of -0.78x EBITDA (Net Cash position), ensuring zero solvency risk.
B11: Valuation Range: | C11: 39 - 64 | E11: Capital Allocation: The valuation is dragged down by declining Asset Turnover due to inefficient cash accumulation (~$12B by 2028) rather than buybacks.
E12: 3. Conclusion: While Nike remains a premier brand with long-term durability (2.5% Terminal Growth), the current price offers no margin of safety. We recommend waiting for a better entry point closer to $45-$50

Sheet Input_History
A1: Historical Financial Data - NIKE, Inc.
B3: Income Statement
B4: (in millions, except per share data) | C4: FY2023 | D4: FY2024 | E4: FY2025
B5: Revenues | C5: 51217 | D5: 51362 | E5: 46309
B6: Cost of Goods Sold | C6: 28925 | D6: 28475 | E6: 26519
B7: Gross Profit | C7: =C5-C6 -> 22292 | D7: =D5-D6 -> 22887 | E7: =E5-E6 -> 19790
B9: Demand Creation Expense | C9: 4060 | D9: 4285 | E9: 4689
B10: Operating Overhead Expense | C10: 11399 | D10: 12291 | E10: 11399
B11: Total Selling & Administrative Expense | C11: 16377 | D11: 16576 | E11: 16088
B12: Interest Expense | C12: 6 | D12: 161 | E12: 107
B13: Other (Income) Expense, net | C13: 280 | D13: 228 | E13: 76
B14: Income Before Income Taxes | C14: 6201 | D14: 6700 | E14: 3885
B15: Income Tax Expense | C15: 1131 | D15: 1000 | E15: 666
B16: NET INCOME | C16: 5070 | D16: 5700 | E16: 3219
B17: Diluted weighted average common shares | C17: 1569.8 | D17: 1529.7 | E17: 1487.6
B19: Balance Sheet
B21: (in millions, except per share data) | C21: FY2024 | D21: FY2025
B22: Assets
B23: Current assets:
B24: Cash and equivalents | C24: 9860 | D24: 7464
B25: Short-term investments | C25: 1722 | D25: 1687
B26: Accounts receivable, net | C26: 4427 | D26: 4717
B27: Inventories | C27: 7519 | D27: 7489
B28: Prepaid expenses and other current assets | C28: 1854 | D28: 2005
B29: Total Current assets: | C29: 25382 | D29: 23362
B30: Property, plant and equipment, net | C30: 5000 | D30: 4828
B31: Operating lease right-of-use assets, net | C31: 2718 | D31: 2712
B32: Identifiable intangible assets, net | C32: 259 | D32: 259
B33: Goodwill | C33: 240 | D33: 240
B34: Deferred income taxes and other assets | C34: 4511 | D34: 5178
B35: Total Assets: | C35: =SUM(C29:C34) -> 38110 | D35: =SUM(D29:D34) -> 36579
B36: Liabilities and Shareholders' Equity
B37: Current liabilities:
B38: Current portion of long-term debt | C38: 1000 | D38: ---
B39: Notes payable | C39: 6 | D39: 5
B40: Accounts payable | C40: 2851 | D40: 3479
B41: Current portion of operating lease liabilities | C41: 477 | D41: 502
B42: Accrued liabilites | C42: 5725 | D42: 5911
B43: Income taxes payable | C43: 534 | D43: 669
B44: Total current liabilites | C44: 10593 | D44: 10566
...

Sheet Assumptions
A1: Assumptions
B3: Assumption Label | C3: FY2026E | D3: FY2027E | E3: FY2028E | F3: Analyst Logic / Source
B4: Revenue Drivers
B5: Revenue Growth % | C5: -0.05 | D5: 0.03 | E5: 0.05 | F5: FY26 impacted by China slowing & franchise resets; recovery begins FY27.
B6: Margin Drivers
B7: Gross Margin % | C7: 0.41 | D7: 0.435 | E7: 0.445 | F7: FY26 hit by promotions/tariffs (down ~300bps); returning to 44% avg.
B8: SG&A as % of Revenue | C8: 0.335 | D8: 0.325 | E8: 0.315 | F8: Costs remain high in FY26 due to Olympics marketing; efficiency improves later.
B9: Effective Tax Rate | C9: 0.205 | D9: 0.18 | E9: 0.17 | F9: Management guidance for FY26 is ~20% due to earnings mix.
B10: CapEx (% of Rev) | C10: 0.03 | D10: 0.035 | E10: 0.035 | F10: Investing in digital supply chain and new ERP systems.
B11: Depreciation (% of PP&E) | C11: 0.15 | D11: 0.15 | E11: 0.15 | F11: Standard straight-line depreciation on historical asset base.
B12: Working Capital
B13: Accounts Receivable Days (DSO) | C13: 37 | D13: 36 | E13: 35 | F13: Slightly elevated in FY26 as wholesalers delay payments; normalizing to 35.
B14: Inventory Days (DIO) | C14: 105 | D14: 100 | E14: 95 | F14: Clearing excess stock in FY26 (current TTM is ~105 days).
B15: Accounts Payable Days (DPO) | C15: 40 | D15: 40 | E15: 40 | F15: Stable supplier payment terms.
B16: Debt & Equity
B17: Interest Rate on Debt | C17: 0.035 | D17: 0.035 | E17: 0.035 | F17: Implied rate on current $8B debt load.
B18: Dividend Payout Ratio | C18: 0.35 | D18: 0.35 | E18: 0.35 | F18: Nike consistently returns cash to shareholders (~30-40% of income).

Sheet Model_Forecast
A1: Model Forecast
B3: Income Statement
B4: (in millions, except per share data) | C4: FY2026E | D4: FY2027E | E4: FY2028E
B5: Revenue | C5: =Input_History!E5*(1+Assumptions!C5) -> 43993.55 | D5: =C5*(1+Assumptions!D5) -> 45313.357 | E5: =D5*(1+Assumptions!E5) -> 47579.024
B6: Cost of Goods Sold | C6: =C5*(1-Assumptions!C7) -> 25956.195 | D6: =D5*(1-Assumptions!D7) -> 25602.046 | E6: =E5*(1-Assumptions!E7) -> 26406.358
B7: Gross Profit | C7: =C5-C6 -> 18037.356 | D7: =D5-D6 -> 19711.31 | E7: =E5-E6 -> 21172.666
B8: SG&A Expenses | C8: =C5*Assumptions!C8 -> 14737.839 | D8: =D5*Assumptions!D8 -> 14726.841 | E8: =E5*Assumptions!E8 -> 14987.393
B9: Operating Income | C9: =C7-C8 -> 3299.5163 | D9: =D7-D8 -> 4984.4692 | E9: =E7-E8 -> 6185.2732
B10: Interest Expense | C10: =Input_History!D45*Assumptions!C17 -> 278.635 | D10: =Input_History!D45*Assumptions!C17 -> 278.635 | E10: =Input_History!D45*Assumptions!C17 -> 278.635
B11: Income Before Tax | C11: =C9-C10 -> 3020.8812 | D11: =D9-D10 -> 4705.8342 | E11: =E9-E10 -> 5906.6382
B12: Income Tax Expense | C12: =C11*Assumptions!C9 -> 619.28066 | D12: =D11*Assumptions!D9 -> 847.05016 | E12: =E11*Assumptions!E9 -> 1004.1285
B13: NET INCOME | C13: =C11-C12 -> 2401.6006 | D13: =D11-D12 -> 3858.7841 | E13: =E11-E12 -> 4902.5097
B17: Balance Sheet
B18: (in millions, except per share data) | C18: FY2026E | D18: FY2027E | E18: FY2028E
B19: Assets
B20: Cash and equivalents | C20: =C329 -> 8074.4777 | D20: =D329 -> 10214.399 | E20: =E329 -> 12801.575
B21: Short-term investments | C21: =Input_History!D25 -> 1687 | D21: =Input_History!D25 -> 1687 | E21: =Input_History!D25 -> 1687
B22: Accounts receivable, net | C22: =(C5/365)*Assumptions!C13 -> 4459.6201 | D22: =(D5/365)*Assumptions!D13 -> 4469.2626 | E22: =(E5/365)*Assumptions!E13 -> 4562.3722
B23: Inventories | C23: =(C6/365)*Assumptions!C14 -> 7466.8505 | D23: =(D6/365)*Assumptions!D14 -> 7014.2593 | E23: =(E6/365)*Assumptions!E14 -> 6872.8878
B24: Prepaid expenses and other current assets | C24: =Input_History!D28 -> 2005 | D24: =Input_History!D28 -> 2005 | E24: =Input_History!D28 -> 2005
B25: Total Current assets: | C25: =SUM(C19:C24) -> 23692.948 | D25: =SUM(D19:D24) -> 25389.921 | E25: =SUM(E19:E24) -> 27928.835
B26: Property, plant and equipment, net | C26: =C297 -> 5423.6065 | D26: =D297 -> 6196.033 | E26: =E297 -> 6931.8939
B27: Operating lease right-of-use assets, net | C27: =Input_History!D31 -> 2712 | D27: =Input_History!D31 -> 2712 | E27: =Input_History!D31 -> 2712
B28: Identifiable intangible assets, net | C28: =Input_History!D32 -> 259 | D28: =Input_History!D32 -> 259 | E28: =Input_History!D32 -> 259
B29: Goodwill | C29: =Input_History!D33 -> 240 | D29: =Input_History!D33 -> 240 | E29: =Input_History!D33 -> 240
B30: Deferred income taxes and other assets | C30: =Input_History!D34 -> 5178 | D30: =Input_History!D34 -> 5178 | E30: =Input_History!D34 -> 5178
B31: Total Assets: | C31: =SUM(C25:C30) -> 37505.555 | D31: =SUM(D25:D30) -> 39974.954 | E31: =SUM(E25:E30) -> 43249.729
B32: Liabilities and Shareholders' Equity | C32: FY2026E | D32: FY2027E | E32: FY2028E
B33: Current portion of long-term debt | C33: =Input_History!D38 -> --- | D33: =Input_History!D38 -> --- | E33: =Input_History!D38 -> ---
B34: Notes payable | C34: =Input_History!D39 -> 5 | D34: =Input_History!D39 -> 5 | E34: =Input_History!D39 -> 5
B35: Accounts payable | C35: =(C6/365)*Assumptions!C15 -> 2844.5145 | D35: =(D6/365)*Assumptions!D15 -> 2805.7037 | E35: =(E6/365)*Assumptions!E15 -> 2893.8475
B36: Current portion of operating lease liabilities | C36: =Input_History!D41 -> 502 | D36: =Input_History!D41 -> 502 | E36: =Input_History!D41 -> 502
B37: Accrued liabilites | C37: =Input_History!D42 -> 5911 | D37: =Input_History!D42 -> 5911 | E37: =Input_History!D42 -> 5911
B38: Income taxes payable | C38: =Input_History!D43 -> 669 | D38: =Input_History!D43 -> 669 | E38: =Input_History!D43 -> 669
B39: Total current liabilites: | C39: =SUM(C33:C38) -> 9931.5145 | D39: =SUM(D33:D38) -> 9892.7037 | E39: =SUM(E33:E38) -> 9980.8475
B40: Long-term debt | C40: =C305 -> 7961 | D40: =D305 -> 7961 | E40: =E305 -> 7961
B41: Operating lease liabilities | C41: =Input_History!D46 -> 2550 | D41: =Input_History!D46 -> 2550 | E41: =Input_History!D46 -> 2550
B42: Deferred income taxes and other liabilities | C42: =Input_History!D47 -> 2289 | D42: =Input_History!D47 -> 2289 | E42: =Input_History!D47 -> 2289
B43: Shareholders' equity:
B44: Common stock at stated value
...

Sheet Summary
A1: SUMMARY
B3: Growth & Profitability | C3: FY2026E | D3: FY2027E | E3: FY2028E
B4: Revenue Growth % | C4: =(Model_Forecast!C5/Input_History!E5)-1 -> -0.05 | D4: =(Model_Forecast!D5/Model_Forecast!C5)-1 -> 0.03 | E4: =(Model_Forecast!E5/Model_Forecast!D5)-1 -> 0.05
B5: Gross Margin % | C5: =Model_Forecast!C7/Model_Forecast!C5 -> 0.41 | D5: =Model_Forecast!D7/Model_Forecast!D5 -> 0.435 | E5: =Model_Forecast!E7/Model_Forecast!E5 -> 0.445
B6: EBIT (Operating) Margin % | C6: =Model_Forecast!C9/Model_Forecast!C5 -> 0.075 | D6: =Model_Forecast!D9/Model_Forecast!D5 -> 0.11 | E6: =Model_Forecast!E9/Model_Forecast!E5 -> 0.13
B7: Net Income Margin % | C7: =Model_Forecast!C13/Model_Forecast!C5 -> 0.054589834 | D7: =Model_Forecast!D13/Model_Forecast!D5 -> 0.085157763 | E7: =Model_Forecast!E13/Model_Forecast!E5 -> 0.10303931
B8: Effective Tax Rate % | C8: =Model_Forecast!C12/Model_Forecast!C11 -> 0.205 | D8: =Model_Forecast!D12/Model_Forecast!D11 -> 0.18 | E8: =Model_Forecast!E12/Model_Forecast!E11 -> 0.17
B12: Returns & Solvency | C12: FY2026E | D12: FY2027E | E12: FY2028E
B13: Return on Equity (ROE) | C13: =Model_Forecast!C13/AVERAGE(Model_Forecast!C51,Input_History!D57) -> 0.17162233 | D13: =Model_Forecast!D13/AVERAGE(Model_Forecast!D51,Model_Forecast!C51) -> 0.24075051 | E13: =Model_Forecast!E13/AVERAGE(Model_Forecast!E51,Model_Forecast!D51) -> 0.25972783
B14: Return on Assets (ROA) | C14: =Model_Forecast!C13/AVERAGE(Model_Forecast!C31,Input_History!D35) -> 0.064834043 | D14: =Model_Forecast!D13/AVERAGE(Model_Forecast!D31,Model_Forecast!C31) -> 0.099606575 | E14: =Model_Forecast!E13/AVERAGE(Model_Forecast!E31,Model_Forecast!D31) -> 0.11781384
B15: Current Ratio | C15: =Model_Forecast!C31/Model_Forecast!C39 -> 3.7764185 | D15: =Model_Forecast!D31/Model_Forecast!D39 -> 4.0408522 | E15: =Model_Forecast!E31/Model_Forecast!E39 -> 4.3332722
B16: Net Debt / EBITDA | C16: =(Model_Forecast!C40 - Model_Forecast!C20) / (Model_Forecast!C9 + Model_Forecast!C310) -> -0.034392236 | D16: =(Model_Forecast!D40 - Model_Forecast!D20) / (Model_Forecast!D9 + Model_Forecast!D310) -> -0.45208402 | E16: =(Model_Forecast!E40 - Model_Forecast!E20) / (Model_Forecast!E9 + Model_Forecast!E310) -> -0.78259678
B17: Asset Turnover | C17: =Model_Forecast!C5/AVERAGE(Model_Forecast!C31,Input_History!D35) -> 1.1876578 | D17: =Model_Forecast!D5/AVERAGE(Model_Forecast!D31,Model_Forecast!C31) -> 1.1696711 | E17: =Model_Forecast!E5/AVERAGE(Model_Forecast!E31,Model_Forecast!D31) -> 1.1433873

Sheet DCF
A1: The DCF Valuation
B3: Free Cash Flow Situation
C4: FY2026E | D4: FY2027E | E4: FY2028E
B5: EBIT (Operating Income) | C5: =Model_Forecast!C9 -> 3299.5163 | D5: =Model_Forecast!D9 -> 4984.4692 | E5: =Model_Forecast!E9 -> 6185.2732
B6: Less: Taxes on EBIT | C6: =-(C5*Assumptions!C9) -> -676.40083 | D6: =-(D5*Assumptions!D9) -> -897.20446 | E6: =-(E5*Assumptions!E9) -> -1051.4964
B7: NOPAT (Net Operating Profit After Tax) | C7: =SUM(C5:C6) -> 2623.1154 | D7: =SUM(D5:D6) -> 4087.2648 | E7: =SUM(E5:E6) -> 5133.7767
B8: Plus: Depreciation & Amortization | C8: =Model_Forecast!C313 -> 724.2 | D8: =Model_Forecast!D313 -> 813.54098 | E8: =Model_Forecast!E313 -> 929.40495
B9: Capital Expenditures | C9: =-Model_Forecast!C295 -> -1319.8065 | D9: =-Model_Forecast!D295 -> -1585.9675 | E9: =-Model_Forecast!E295 -> -1665.2659
B10: Change in Net Working Capital | C10: =SUM(Model_Forecast!C315:C320) -> -354.95614 | D10: =SUM(Model_Forecast!D315:D320) -> 404.13801 | E10: =SUM(Model_Forecast!E315:E320) -> 136.40562
B11: Unlevered Free Cash Flow (UFCF) | C11: =SUM(C7:C10) -> 1672.5528 | D11: =SUM(D7:D10) -> 3718.9763 | E11: =SUM(E7:E10) -> 4534.3214
B13: Valuation Assumptions
C14: FY2026E | D14: FY2027E | E14: FY2028E
B15: WACC (Discount Rate) | C15: 0.085 | D15: 0.085 | E15: 0.085
B16: Terminal Growth Rate | C16: 0.025 | D16: 0.025 | E16: 0.025
B17: Shares Outstanding (Millions) | C17: =Input_History!E17 -> 1487.6 | D17: =Input_History!E17 -> 1487.6 | E17: =Input_History!E17 -> 1487.6
B18: Net Debt (Cash) | C18: =Model_Forecast!C40-Model_Forecast!C20 -> -113.47774 | D18: =Model_Forecast!D40-Model_Forecast!D20 -> -2253.3989 | E18: =Model_Forecast!E40-Model_Forecast!E20 -> -4840.5749
B20: The Terminal Value | C20: - | D20: - | E20: =(E11*(1+C16))/(C15-C16) -> 77461.325
B21: Discount Period | C21: 0.5 | D21: 1.5 | E21: 2.5
B22: Discount Factor | C22: =1/(1+C15)^C21 -> 0.96003072 | D22: =1/(1+D15)^D21 -> 0.88482094 | E22: =1/(1+E15)^E21 -> 0.81550317
B23: PV of Free Cash Flow | C23: =C11*C22 -> 1605.702 | D23: =D11*D22 -> 3290.6281 | E23: =E11*E22 -> 3697.7535
B24: PV of Terminal Value | C24: - | D24: - | E24: =E20*E22 -> 63169.956
B25: SUM of PV of FCF | C25: =SUM(C23:E23) -> 8594.0836 | D25: - | E25: -
B26: Plus: PV of Terminal Value | C26: =E24 -> 63169.956 | D26: - | E26: -
B27: Enterprise Value | C27: =SUM(C25:C26) -> 71764.04 | D27: - | E27: -
B28: Less: Net Debt | C28: =C18 -> -113.47774 | D28: - | E28: -
B29: Equity Value | C29: =SUM(C27:C28) -> 71650.562 | D29: - | E29: -
B30: Implied Share Value | C30: =C29/E17 -> 48.165207 | D30: - | E30: -
B33: Sensitivity Analysis: Share Price.
C34: Growth | D34: 0.075 | E34: 0.08 | F34: 0.085 | G34: 0.09 | H34: 0.095
C35: 0.02 | D35: 50 | E35: 45 | F35: 41 | G35: 37 | H35: 34
C36: 0.0225 | D36: 53 | E36: 49 | F36: 44 | G36: 40 | H36: 37
C37: 0.025 | D37: 57 | E37: 52 | F37: 48 | G37: 44 | H37: 40
C38: 0.0275 | D38: 60 | E38: 55 | F38: 52 | G38: 47 | H38: 43
C39: 0.03 | D39: 64 | E39: 59 | F39: 55 | G39: 50 | H39: 46
